<?xml version="1.0" encoding="utf-8"?>
<robot name="strawberry_plant">
  <link name="world"/>
  <material name="Blue">
    <color rgba="0.28 0.52 0.92 1.0"/>0
  </material>
  <material name="red">
    <color rgba="0.9 0.2 0.2 1.0"/>0
  </material>
  <material name="green">
    <color rgba="0.25 0.9 0.2 1.0"/>0
  </material>

  <link name="Upperstem">
    <visual>
      <geometry>
        <sphere radius="0.01"/>
      </geometry>
      <origin rpy="0 0 0" xyz="0 0 0"/>
      <material name="green"/>
    </visual>
  </link>

  <joint name="joint0" type="fixed">
    <parent link="world"/>
    <child link="Upperstem"/>
    <origin rpy="0 0 0" xyz="0 0 0"/>
  </joint>

  <link name="stem">
    <visual>
      <geometry>
        <cylinder radius="0.001" length="0.1"/>
      </geometry>
      <origin rpy="1.57 0 0" xyz="0 0.075 0"/>
      <material name="green"/>
    </visual>
    <collision>
      <geometry>
        <cylinder radius="0.001" length="0.1"/>
      </geometry>
      <origin rpy="1.57 0 0" xyz="0 0.075 0"/>
    </collision>
    <inertial>
      <origin rpy="1.57 0 0" xyz="0 0.075 0"/>
      <mass value="0.01"/>
        <inertia  ixx="0.00001" ixy="0.0" ixz="0.0"
                  iyy="0.00001" iyz="0.0"
                  izz="0.00001" />    
    </inertial>
  </link>

  <joint name="joint1" type="continuous">
    <parent link="Upperstem"/>
    <child link="stem"/>
    <origin rpy="0 0 0.75" xyz="0 0 0"/>
    <dynamics damping="0.0" friction="0.0" spring="0.0"/>
  </joint>

  <link name="strawberry">
    <visual>
      <geometry>
        <mesh filename="meshes/strawberry.obj" scale="0.01 0.01 0.01"/>
      </geometry>
      <origin rpy="1.57 0 0" xyz="-0.005 0.15 -0.005"/>
      <material name="red"/>
    </visual>
    <collision>
      <geometry>
        <mesh filename="meshes/strawberry.obj" scale="0.01 0.01 0.01"/>
      </geometry>
      <origin rpy="1.57 0 0" xyz="-0.005 0.15 -0.005"/>
    </collision>
    <inertial>
      <origin rpy="1.57 0 0" xyz="-0.005 0.15 -0.005"/>
      <mass value="0.04"/>
        <inertia  ixx="0.00001" ixy="0.0" ixz="0.0"
                  iyy="0.00001" iyz="0.0"
                  izz="0.00001" />    
    </inertial>
  </link>

  <joint name="joint2" type="fixed">
    <parent link="stem"/>
    <child link="strawberry"/>
    <origin rpy="0 0 0" xyz="0 0 0"/>
  </joint>


<!-- /////////////////////////////////////////////////////////////////////////////////////////////////////////////////////////////////////////////////////////////////////////////////////////////////////////////////////////// -->

<!--  <link name="link2">
    <visual>
      <geometry>
        <sphere radius="0.05"/>
      </geometry>
      <origin rpy="0 0 0" xyz="0 0.5 0"/>
      <material name="Red"/>
    </visual>
    <collision>
      <geometry>
        <sphere radius="0.05"/>
      </geometry>
      <origin rpy="0 0 0" xyz="0 0.5 0"/>
    </collision>
    <inertial>
      <origin rpy="0 0 0" xyz="0 0.5 0"/>
      <mass value="2.16"/>
      <inertia ixx="0.00539427" ixy="0" ixz="0" iyy="0.0048979" iyz="0" izz="0.00311573"/>
    </inertial>
  </link>
  <joint name="joint2" type="continuous">
    <parent link="link1"/>
    <child link="link2"/>
    <origin rpy="0 0 0" xyz="0 0.5 0"/>
    <axis xyz="1 0 0"/>
    <dynamics damping="1.0" friction="1.0"/>
  </joint>
  <link name="link3">
    <visual>
      <geometry>
        <sphere radius="0.05"/>
      </geometry>
      <origin rpy="0 0 0" xyz="0 0.5 0"/>
      <material name="Red"/>
    </visual>
    <collision>
      <geometry>
        <sphere radius="0.05"/>
      </geometry>
      <origin rpy="0 0 0" xyz="0 0.5 0"/>
    </collision>
    <inertial>
      <origin rpy="0 0 0" xyz="0 0.5 0"/>
      <mass value="2.16"/>
      <inertia ixx="0.00539427" ixy="0" ixz="0" iyy="0.0048979" iyz="0" izz="0.00311573"/>
    </inertial>
  </link>
  <joint name="joint3" type="continuous">
    <parent link="link2"/>
    <child link="link3"/>
    <origin rpy="0 0 0" xyz="0 0.5 0"/>
    <axis xyz="1 0 0"/>
    <dynamics damping="1.0" friction="1.0"/>
  </joint>
   <link name="link4">
    <visual>
      <geometry>
        <sphere radius="0.05"/>
      </geometry>
      <origin rpy="0 0 0" xyz="0 0.5 0"/>
      <material name="Red"/>
    </visual>
    <collision>
      <geometry>
        <sphere radius="0.05"/>
      </geometry>
      <origin rpy="0 0 0" xyz="0 0.5 0"/>
    </collision>
    <inertial>
      <origin rpy="0 0 0" xyz="0 0.5 0"/>
      <mass value="2.16"/>
      <inertia ixx="0.00539427" ixy="0" ixz="0" iyy="0.0048979" iyz="0" izz="0.00311573"/>
    </inertial>
  </link>
  <joint name="joint4" type="continuous">
    <parent link="link3"/>
    <child link="link4"/>
    <origin rpy="0 0 0" xyz="0 0.5 0"/>
    <axis xyz="1 0 0"/>
    <dynamics damping="1.0" friction="1.0"/>
  </joint> -->
</robot>
